{
  "nbformat": 4,
  "nbformat_minor": 0,
  "metadata": {
    "colab": {
      "provenance": [],
      "authorship_tag": "ABX9TyPFpEBqa3dFJlY8WfWFA63v",
      "include_colab_link": true
    },
    "kernelspec": {
      "name": "python3",
      "display_name": "Python 3"
    },
    "language_info": {
      "name": "python"
    }
  },
  "cells": [
    {
      "cell_type": "markdown",
      "metadata": {
        "id": "view-in-github",
        "colab_type": "text"
      },
      "source": [
        "<a href=\"https://colab.research.google.com/github/ashfaq-polit/Automation-Codes/blob/main/API_Creation.ipynb\" target=\"_parent\"><img src=\"https://colab.research.google.com/assets/colab-badge.svg\" alt=\"Open In Colab\"/></a>"
      ]
    },
    {
      "cell_type": "code",
      "source": [
        "!pip install pyngrok"
      ],
      "metadata": {
        "colab": {
          "base_uri": "https://localhost:8080/"
        },
        "id": "UR0fMZj3RpwF",
        "outputId": "3c5f7ab8-2260-4159-bdb4-5bbdf89189e6"
      },
      "execution_count": 3,
      "outputs": [
        {
          "output_type": "stream",
          "name": "stdout",
          "text": [
            "Collecting pyngrok\n",
            "  Downloading pyngrok-7.2.11-py3-none-any.whl.metadata (9.4 kB)\n",
            "Requirement already satisfied: PyYAML>=5.1 in /usr/local/lib/python3.11/dist-packages (from pyngrok) (6.0.2)\n",
            "Downloading pyngrok-7.2.11-py3-none-any.whl (25 kB)\n",
            "Installing collected packages: pyngrok\n",
            "Successfully installed pyngrok-7.2.11\n"
          ]
        }
      ]
    },
    {
      "cell_type": "code",
      "execution_count": 12,
      "metadata": {
        "id": "XYpkhAZtvQDI"
      },
      "outputs": [],
      "source": [
        "from flask import Flask\n",
        "\n",
        "app = Flask(__name__)\n",
        "\n",
        "@app.route('/')\n",
        "\n",
        "def hello():\n",
        "\n",
        "    return \"Hello world!\""
      ]
    },
    {
      "cell_type": "code",
      "source": [
        "# !ngrok config add-authtoken 2ymqzG3rvZxPu5HT8mh9jOBkfeg_6vzFZGe4mduEVXfMBsjdw"
      ],
      "metadata": {
        "colab": {
          "base_uri": "https://localhost:8080/"
        },
        "id": "gWNyMc-iF_sK",
        "outputId": "b544cb59-9df4-4251-b07b-27ba58139bd6"
      },
      "execution_count": 20,
      "outputs": [
        {
          "output_type": "stream",
          "name": "stdout",
          "text": [
            "Authtoken saved to configuration file: /root/.config/ngrok/ngrok.yml\n"
          ]
        }
      ]
    },
    {
      "cell_type": "code",
      "source": [
        "from flask import Flask, jsonify, request\n",
        "from pyngrok import ngrok\n",
        "from google.colab import userdata\n",
        "\n",
        "app = Flask(__name__)\n",
        "\n",
        "# Replace with your ngrok authtoken\n",
        "NGROK_AUTHTOKEN = userdata.get(\"NGROK_AUTH_TOKEN\")\n",
        "\n",
        "# Authenticate ngrok\n",
        "ngrok.set_auth_token(NGROK_AUTHTOKEN)\n",
        "\n",
        "# Open a ngrok tunnel to the Flask app's port\n",
        "# The port should match the port Flask is running on (default is 5000)\n",
        "public_url = ngrok.connect(5000).public_url\n",
        "print(f\" * ngrok tunnel \\\"{public_url}\\\" -> \\\"http://127.0.0.0:5000\\\"\")\n",
        "\n",
        "# Update the app with the ngrok tunnel URL\n",
        "app.config[\"BASE_URL\"] = public_url\n",
        "\n",
        "@app.route('/')\n",
        "def hello():\n",
        "    return \"Hello world!\"\n",
        "\n",
        "@app.route('/items', methods=['GET'])\n",
        "def get_items():\n",
        "    # Logic to retrieve items\n",
        "    items = [{\"id\": 1, \"name\": \"item1\"}, {\"id\": 2, \"name\": \"item2\"}]\n",
        "    return jsonify(items)\n",
        "\n",
        "@app.route('/items', methods=['POST'])\n",
        "def create_item():\n",
        "    # Logic to create a new item\n",
        "    new_item_data = request.json # Get JSON data from the request\n",
        "    # Here you would typically process the data and add it to a database or list\n",
        "    # For demonstration, let's just add an ID to the received data\n",
        "    new_item = {\"id\": len(items) + 1 if 'items' in globals() else 1, **new_item_data} # Create a new item with an ID\n",
        "    # In a real application, you would save new_item and then return it\n",
        "    return jsonify(new_item), 201\n",
        "\n",
        "if __name__ == \"__main__\":\n",
        "    # Use the Flask development server to run the app\n",
        "    app.run()"
      ],
      "metadata": {
        "colab": {
          "base_uri": "https://localhost:8080/"
        },
        "id": "54bQUxKK_wut",
        "outputId": "0a607a4f-faf1-4dd0-fbe5-ea37aad8b57a"
      },
      "execution_count": 10,
      "outputs": [
        {
          "output_type": "stream",
          "name": "stdout",
          "text": [
            " * ngrok tunnel \"https://6f51-34-75-54-160.ngrok-free.app\" -> \"http://127.0.0.0:5000\"\n",
            " * Serving Flask app '__main__'\n",
            " * Debug mode: off\n"
          ]
        },
        {
          "output_type": "stream",
          "name": "stderr",
          "text": [
            "INFO:werkzeug:\u001b[31m\u001b[1mWARNING: This is a development server. Do not use it in a production deployment. Use a production WSGI server instead.\u001b[0m\n",
            " * Running on http://127.0.0.1:5000\n",
            "INFO:werkzeug:\u001b[33mPress CTRL+C to quit\u001b[0m\n",
            "ERROR:root:Unexpected exception finding object shape\n",
            "Traceback (most recent call last):\n",
            "  File \"/usr/local/lib/python3.11/dist-packages/google/colab/_debugpy_repr.py\", line 54, in get_shape\n",
            "    shape = getattr(obj, 'shape', None)\n",
            "            ^^^^^^^^^^^^^^^^^^^^^^^^^^^\n",
            "  File \"/usr/local/lib/python3.11/dist-packages/werkzeug/local.py\", line 318, in __get__\n",
            "    obj = instance._get_current_object()\n",
            "          ^^^^^^^^^^^^^^^^^^^^^^^^^^^^^^\n",
            "  File \"/usr/local/lib/python3.11/dist-packages/werkzeug/local.py\", line 519, in _get_current_object\n",
            "    raise RuntimeError(unbound_message) from None\n",
            "RuntimeError: Working outside of request context.\n",
            "\n",
            "This typically means that you attempted to use functionality that needed\n",
            "an active HTTP request. Consult the documentation on testing for\n",
            "information about how to avoid this problem.\n",
            "ERROR:root:Unexpected exception finding object shape\n",
            "Traceback (most recent call last):\n",
            "  File \"/usr/local/lib/python3.11/dist-packages/google/colab/_debugpy_repr.py\", line 54, in get_shape\n",
            "    shape = getattr(obj, 'shape', None)\n",
            "            ^^^^^^^^^^^^^^^^^^^^^^^^^^^\n",
            "  File \"/usr/local/lib/python3.11/dist-packages/werkzeug/local.py\", line 318, in __get__\n",
            "    obj = instance._get_current_object()\n",
            "          ^^^^^^^^^^^^^^^^^^^^^^^^^^^^^^\n",
            "  File \"/usr/local/lib/python3.11/dist-packages/werkzeug/local.py\", line 519, in _get_current_object\n",
            "    raise RuntimeError(unbound_message) from None\n",
            "RuntimeError: Working outside of request context.\n",
            "\n",
            "This typically means that you attempted to use functionality that needed\n",
            "an active HTTP request. Consult the documentation on testing for\n",
            "information about how to avoid this problem.\n",
            "ERROR:root:Unexpected exception finding object shape\n",
            "Traceback (most recent call last):\n",
            "  File \"/usr/local/lib/python3.11/dist-packages/google/colab/_debugpy_repr.py\", line 54, in get_shape\n",
            "    shape = getattr(obj, 'shape', None)\n",
            "            ^^^^^^^^^^^^^^^^^^^^^^^^^^^\n",
            "  File \"/usr/local/lib/python3.11/dist-packages/werkzeug/local.py\", line 318, in __get__\n",
            "    obj = instance._get_current_object()\n",
            "          ^^^^^^^^^^^^^^^^^^^^^^^^^^^^^^\n",
            "  File \"/usr/local/lib/python3.11/dist-packages/werkzeug/local.py\", line 519, in _get_current_object\n",
            "    raise RuntimeError(unbound_message) from None\n",
            "RuntimeError: Working outside of request context.\n",
            "\n",
            "This typically means that you attempted to use functionality that needed\n",
            "an active HTTP request. Consult the documentation on testing for\n",
            "information about how to avoid this problem.\n",
            "ERROR:root:Unexpected exception finding object shape\n",
            "Traceback (most recent call last):\n",
            "  File \"/usr/local/lib/python3.11/dist-packages/google/colab/_debugpy_repr.py\", line 54, in get_shape\n",
            "    shape = getattr(obj, 'shape', None)\n",
            "            ^^^^^^^^^^^^^^^^^^^^^^^^^^^\n",
            "  File \"/usr/local/lib/python3.11/dist-packages/werkzeug/local.py\", line 318, in __get__\n",
            "    obj = instance._get_current_object()\n",
            "          ^^^^^^^^^^^^^^^^^^^^^^^^^^^^^^\n",
            "  File \"/usr/local/lib/python3.11/dist-packages/werkzeug/local.py\", line 519, in _get_current_object\n",
            "    raise RuntimeError(unbound_message) from None\n",
            "RuntimeError: Working outside of request context.\n",
            "\n",
            "This typically means that you attempted to use functionality that needed\n",
            "an active HTTP request. Consult the documentation on testing for\n",
            "information about how to avoid this problem.\n",
            "ERROR:root:Unexpected exception finding object shape\n",
            "Traceback (most recent call last):\n",
            "  File \"/usr/local/lib/python3.11/dist-packages/google/colab/_debugpy_repr.py\", line 54, in get_shape\n",
            "    shape = getattr(obj, 'shape', None)\n",
            "            ^^^^^^^^^^^^^^^^^^^^^^^^^^^\n",
            "  File \"/usr/local/lib/python3.11/dist-packages/werkzeug/local.py\", line 318, in __get__\n",
            "    obj = instance._get_current_object()\n",
            "          ^^^^^^^^^^^^^^^^^^^^^^^^^^^^^^\n",
            "  File \"/usr/local/lib/python3.11/dist-packages/werkzeug/local.py\", line 519, in _get_current_object\n",
            "    raise RuntimeError(unbound_message) from None\n",
            "RuntimeError: Working outside of request context.\n",
            "\n",
            "This typically means that you attempted to use functionality that needed\n",
            "an active HTTP request. Consult the documentation on testing for\n",
            "information about how to avoid this problem.\n",
            "ERROR:root:Unexpected exception finding object shape\n",
            "Traceback (most recent call last):\n",
            "  File \"/usr/local/lib/python3.11/dist-packages/google/colab/_debugpy_repr.py\", line 54, in get_shape\n",
            "    shape = getattr(obj, 'shape', None)\n",
            "            ^^^^^^^^^^^^^^^^^^^^^^^^^^^\n",
            "  File \"/usr/local/lib/python3.11/dist-packages/werkzeug/local.py\", line 318, in __get__\n",
            "    obj = instance._get_current_object()\n",
            "          ^^^^^^^^^^^^^^^^^^^^^^^^^^^^^^\n",
            "  File \"/usr/local/lib/python3.11/dist-packages/werkzeug/local.py\", line 519, in _get_current_object\n",
            "    raise RuntimeError(unbound_message) from None\n",
            "RuntimeError: Working outside of request context.\n",
            "\n",
            "This typically means that you attempted to use functionality that needed\n",
            "an active HTTP request. Consult the documentation on testing for\n",
            "information about how to avoid this problem.\n",
            "ERROR:root:Unexpected exception finding object shape\n",
            "Traceback (most recent call last):\n",
            "  File \"/usr/local/lib/python3.11/dist-packages/google/colab/_debugpy_repr.py\", line 54, in get_shape\n",
            "    shape = getattr(obj, 'shape', None)\n",
            "            ^^^^^^^^^^^^^^^^^^^^^^^^^^^\n",
            "  File \"/usr/local/lib/python3.11/dist-packages/werkzeug/local.py\", line 318, in __get__\n",
            "    obj = instance._get_current_object()\n",
            "          ^^^^^^^^^^^^^^^^^^^^^^^^^^^^^^\n",
            "  File \"/usr/local/lib/python3.11/dist-packages/werkzeug/local.py\", line 519, in _get_current_object\n",
            "    raise RuntimeError(unbound_message) from None\n",
            "RuntimeError: Working outside of request context.\n",
            "\n",
            "This typically means that you attempted to use functionality that needed\n",
            "an active HTTP request. Consult the documentation on testing for\n",
            "information about how to avoid this problem.\n",
            "ERROR:root:Unexpected exception finding object shape\n",
            "Traceback (most recent call last):\n",
            "  File \"/usr/local/lib/python3.11/dist-packages/google/colab/_debugpy_repr.py\", line 54, in get_shape\n",
            "    shape = getattr(obj, 'shape', None)\n",
            "            ^^^^^^^^^^^^^^^^^^^^^^^^^^^\n",
            "  File \"/usr/local/lib/python3.11/dist-packages/werkzeug/local.py\", line 318, in __get__\n",
            "    obj = instance._get_current_object()\n",
            "          ^^^^^^^^^^^^^^^^^^^^^^^^^^^^^^\n",
            "  File \"/usr/local/lib/python3.11/dist-packages/werkzeug/local.py\", line 519, in _get_current_object\n",
            "    raise RuntimeError(unbound_message) from None\n",
            "RuntimeError: Working outside of request context.\n",
            "\n",
            "This typically means that you attempted to use functionality that needed\n",
            "an active HTTP request. Consult the documentation on testing for\n",
            "information about how to avoid this problem.\n",
            "ERROR:root:Unexpected exception finding object shape\n",
            "Traceback (most recent call last):\n",
            "  File \"/usr/local/lib/python3.11/dist-packages/google/colab/_debugpy_repr.py\", line 54, in get_shape\n",
            "    shape = getattr(obj, 'shape', None)\n",
            "            ^^^^^^^^^^^^^^^^^^^^^^^^^^^\n",
            "  File \"/usr/local/lib/python3.11/dist-packages/werkzeug/local.py\", line 318, in __get__\n",
            "    obj = instance._get_current_object()\n",
            "          ^^^^^^^^^^^^^^^^^^^^^^^^^^^^^^\n",
            "  File \"/usr/local/lib/python3.11/dist-packages/werkzeug/local.py\", line 519, in _get_current_object\n",
            "    raise RuntimeError(unbound_message) from None\n",
            "RuntimeError: Working outside of request context.\n",
            "\n",
            "This typically means that you attempted to use functionality that needed\n",
            "an active HTTP request. Consult the documentation on testing for\n",
            "information about how to avoid this problem.\n",
            "ERROR:root:Unexpected exception finding object shape\n",
            "Traceback (most recent call last):\n",
            "  File \"/usr/local/lib/python3.11/dist-packages/google/colab/_debugpy_repr.py\", line 54, in get_shape\n",
            "    shape = getattr(obj, 'shape', None)\n",
            "            ^^^^^^^^^^^^^^^^^^^^^^^^^^^\n",
            "  File \"/usr/local/lib/python3.11/dist-packages/werkzeug/local.py\", line 318, in __get__\n",
            "    obj = instance._get_current_object()\n",
            "          ^^^^^^^^^^^^^^^^^^^^^^^^^^^^^^\n",
            "  File \"/usr/local/lib/python3.11/dist-packages/werkzeug/local.py\", line 519, in _get_current_object\n",
            "    raise RuntimeError(unbound_message) from None\n",
            "RuntimeError: Working outside of request context.\n",
            "\n",
            "This typically means that you attempted to use functionality that needed\n",
            "an active HTTP request. Consult the documentation on testing for\n",
            "information about how to avoid this problem.\n",
            "ERROR:root:Unexpected exception finding object shape\n",
            "Traceback (most recent call last):\n",
            "  File \"/usr/local/lib/python3.11/dist-packages/google/colab/_debugpy_repr.py\", line 54, in get_shape\n",
            "    shape = getattr(obj, 'shape', None)\n",
            "            ^^^^^^^^^^^^^^^^^^^^^^^^^^^\n",
            "  File \"/usr/local/lib/python3.11/dist-packages/werkzeug/local.py\", line 318, in __get__\n",
            "    obj = instance._get_current_object()\n",
            "          ^^^^^^^^^^^^^^^^^^^^^^^^^^^^^^\n",
            "  File \"/usr/local/lib/python3.11/dist-packages/werkzeug/local.py\", line 519, in _get_current_object\n",
            "    raise RuntimeError(unbound_message) from None\n",
            "RuntimeError: Working outside of request context.\n",
            "\n",
            "This typically means that you attempted to use functionality that needed\n",
            "an active HTTP request. Consult the documentation on testing for\n",
            "information about how to avoid this problem.\n",
            "ERROR:root:Unexpected exception finding object shape\n",
            "Traceback (most recent call last):\n",
            "  File \"/usr/local/lib/python3.11/dist-packages/google/colab/_debugpy_repr.py\", line 54, in get_shape\n",
            "    shape = getattr(obj, 'shape', None)\n",
            "            ^^^^^^^^^^^^^^^^^^^^^^^^^^^\n",
            "  File \"/usr/local/lib/python3.11/dist-packages/werkzeug/local.py\", line 318, in __get__\n",
            "    obj = instance._get_current_object()\n",
            "          ^^^^^^^^^^^^^^^^^^^^^^^^^^^^^^\n",
            "  File \"/usr/local/lib/python3.11/dist-packages/werkzeug/local.py\", line 519, in _get_current_object\n",
            "    raise RuntimeError(unbound_message) from None\n",
            "RuntimeError: Working outside of request context.\n",
            "\n",
            "This typically means that you attempted to use functionality that needed\n",
            "an active HTTP request. Consult the documentation on testing for\n",
            "information about how to avoid this problem.\n",
            "ERROR:root:Unexpected exception finding object shape\n",
            "Traceback (most recent call last):\n",
            "  File \"/usr/local/lib/python3.11/dist-packages/google/colab/_debugpy_repr.py\", line 54, in get_shape\n",
            "    shape = getattr(obj, 'shape', None)\n",
            "            ^^^^^^^^^^^^^^^^^^^^^^^^^^^\n",
            "  File \"/usr/local/lib/python3.11/dist-packages/werkzeug/local.py\", line 318, in __get__\n",
            "    obj = instance._get_current_object()\n",
            "          ^^^^^^^^^^^^^^^^^^^^^^^^^^^^^^\n",
            "  File \"/usr/local/lib/python3.11/dist-packages/werkzeug/local.py\", line 519, in _get_current_object\n",
            "    raise RuntimeError(unbound_message) from None\n",
            "RuntimeError: Working outside of request context.\n",
            "\n",
            "This typically means that you attempted to use functionality that needed\n",
            "an active HTTP request. Consult the documentation on testing for\n",
            "information about how to avoid this problem.\n",
            "ERROR:root:Unexpected exception finding object shape\n",
            "Traceback (most recent call last):\n",
            "  File \"/usr/local/lib/python3.11/dist-packages/google/colab/_debugpy_repr.py\", line 54, in get_shape\n",
            "    shape = getattr(obj, 'shape', None)\n",
            "            ^^^^^^^^^^^^^^^^^^^^^^^^^^^\n",
            "  File \"/usr/local/lib/python3.11/dist-packages/werkzeug/local.py\", line 318, in __get__\n",
            "    obj = instance._get_current_object()\n",
            "          ^^^^^^^^^^^^^^^^^^^^^^^^^^^^^^\n",
            "  File \"/usr/local/lib/python3.11/dist-packages/werkzeug/local.py\", line 519, in _get_current_object\n",
            "    raise RuntimeError(unbound_message) from None\n",
            "RuntimeError: Working outside of request context.\n",
            "\n",
            "This typically means that you attempted to use functionality that needed\n",
            "an active HTTP request. Consult the documentation on testing for\n",
            "information about how to avoid this problem.\n",
            "ERROR:root:Unexpected exception finding object shape\n",
            "Traceback (most recent call last):\n",
            "  File \"/usr/local/lib/python3.11/dist-packages/google/colab/_debugpy_repr.py\", line 54, in get_shape\n",
            "    shape = getattr(obj, 'shape', None)\n",
            "            ^^^^^^^^^^^^^^^^^^^^^^^^^^^\n",
            "  File \"/usr/local/lib/python3.11/dist-packages/werkzeug/local.py\", line 318, in __get__\n",
            "    obj = instance._get_current_object()\n",
            "          ^^^^^^^^^^^^^^^^^^^^^^^^^^^^^^\n",
            "  File \"/usr/local/lib/python3.11/dist-packages/werkzeug/local.py\", line 519, in _get_current_object\n",
            "    raise RuntimeError(unbound_message) from None\n",
            "RuntimeError: Working outside of request context.\n",
            "\n",
            "This typically means that you attempted to use functionality that needed\n",
            "an active HTTP request. Consult the documentation on testing for\n",
            "information about how to avoid this problem.\n",
            "ERROR:root:Unexpected exception finding object shape\n",
            "Traceback (most recent call last):\n",
            "  File \"/usr/local/lib/python3.11/dist-packages/google/colab/_debugpy_repr.py\", line 54, in get_shape\n",
            "    shape = getattr(obj, 'shape', None)\n",
            "            ^^^^^^^^^^^^^^^^^^^^^^^^^^^\n",
            "  File \"/usr/local/lib/python3.11/dist-packages/werkzeug/local.py\", line 318, in __get__\n",
            "    obj = instance._get_current_object()\n",
            "          ^^^^^^^^^^^^^^^^^^^^^^^^^^^^^^\n",
            "  File \"/usr/local/lib/python3.11/dist-packages/werkzeug/local.py\", line 519, in _get_current_object\n",
            "    raise RuntimeError(unbound_message) from None\n",
            "RuntimeError: Working outside of request context.\n",
            "\n",
            "This typically means that you attempted to use functionality that needed\n",
            "an active HTTP request. Consult the documentation on testing for\n",
            "information about how to avoid this problem.\n",
            "ERROR:root:Unexpected exception finding object shape\n",
            "Traceback (most recent call last):\n",
            "  File \"/usr/local/lib/python3.11/dist-packages/google/colab/_debugpy_repr.py\", line 54, in get_shape\n",
            "    shape = getattr(obj, 'shape', None)\n",
            "            ^^^^^^^^^^^^^^^^^^^^^^^^^^^\n",
            "  File \"/usr/local/lib/python3.11/dist-packages/werkzeug/local.py\", line 318, in __get__\n",
            "    obj = instance._get_current_object()\n",
            "          ^^^^^^^^^^^^^^^^^^^^^^^^^^^^^^\n",
            "  File \"/usr/local/lib/python3.11/dist-packages/werkzeug/local.py\", line 519, in _get_current_object\n",
            "    raise RuntimeError(unbound_message) from None\n",
            "RuntimeError: Working outside of request context.\n",
            "\n",
            "This typically means that you attempted to use functionality that needed\n",
            "an active HTTP request. Consult the documentation on testing for\n",
            "information about how to avoid this problem.\n",
            "ERROR:root:Unexpected exception finding object shape\n",
            "Traceback (most recent call last):\n",
            "  File \"/usr/local/lib/python3.11/dist-packages/google/colab/_debugpy_repr.py\", line 54, in get_shape\n",
            "    shape = getattr(obj, 'shape', None)\n",
            "            ^^^^^^^^^^^^^^^^^^^^^^^^^^^\n",
            "  File \"/usr/local/lib/python3.11/dist-packages/werkzeug/local.py\", line 318, in __get__\n",
            "    obj = instance._get_current_object()\n",
            "          ^^^^^^^^^^^^^^^^^^^^^^^^^^^^^^\n",
            "  File \"/usr/local/lib/python3.11/dist-packages/werkzeug/local.py\", line 519, in _get_current_object\n",
            "    raise RuntimeError(unbound_message) from None\n",
            "RuntimeError: Working outside of request context.\n",
            "\n",
            "This typically means that you attempted to use functionality that needed\n",
            "an active HTTP request. Consult the documentation on testing for\n",
            "information about how to avoid this problem.\n",
            "ERROR:root:Unexpected exception finding object shape\n",
            "Traceback (most recent call last):\n",
            "  File \"/usr/local/lib/python3.11/dist-packages/google/colab/_debugpy_repr.py\", line 54, in get_shape\n",
            "    shape = getattr(obj, 'shape', None)\n",
            "            ^^^^^^^^^^^^^^^^^^^^^^^^^^^\n",
            "  File \"/usr/local/lib/python3.11/dist-packages/werkzeug/local.py\", line 318, in __get__\n",
            "    obj = instance._get_current_object()\n",
            "          ^^^^^^^^^^^^^^^^^^^^^^^^^^^^^^\n",
            "  File \"/usr/local/lib/python3.11/dist-packages/werkzeug/local.py\", line 519, in _get_current_object\n",
            "    raise RuntimeError(unbound_message) from None\n",
            "RuntimeError: Working outside of request context.\n",
            "\n",
            "This typically means that you attempted to use functionality that needed\n",
            "an active HTTP request. Consult the documentation on testing for\n",
            "information about how to avoid this problem.\n",
            "ERROR:root:Unexpected exception finding object shape\n",
            "Traceback (most recent call last):\n",
            "  File \"/usr/local/lib/python3.11/dist-packages/google/colab/_debugpy_repr.py\", line 54, in get_shape\n",
            "    shape = getattr(obj, 'shape', None)\n",
            "            ^^^^^^^^^^^^^^^^^^^^^^^^^^^\n",
            "  File \"/usr/local/lib/python3.11/dist-packages/werkzeug/local.py\", line 318, in __get__\n",
            "    obj = instance._get_current_object()\n",
            "          ^^^^^^^^^^^^^^^^^^^^^^^^^^^^^^\n",
            "  File \"/usr/local/lib/python3.11/dist-packages/werkzeug/local.py\", line 519, in _get_current_object\n",
            "    raise RuntimeError(unbound_message) from None\n",
            "RuntimeError: Working outside of request context.\n",
            "\n",
            "This typically means that you attempted to use functionality that needed\n",
            "an active HTTP request. Consult the documentation on testing for\n",
            "information about how to avoid this problem.\n",
            "ERROR:root:Unexpected exception finding object shape\n",
            "Traceback (most recent call last):\n",
            "  File \"/usr/local/lib/python3.11/dist-packages/google/colab/_debugpy_repr.py\", line 54, in get_shape\n",
            "    shape = getattr(obj, 'shape', None)\n",
            "            ^^^^^^^^^^^^^^^^^^^^^^^^^^^\n",
            "  File \"/usr/local/lib/python3.11/dist-packages/werkzeug/local.py\", line 318, in __get__\n",
            "    obj = instance._get_current_object()\n",
            "          ^^^^^^^^^^^^^^^^^^^^^^^^^^^^^^\n",
            "  File \"/usr/local/lib/python3.11/dist-packages/werkzeug/local.py\", line 519, in _get_current_object\n",
            "    raise RuntimeError(unbound_message) from None\n",
            "RuntimeError: Working outside of request context.\n",
            "\n",
            "This typically means that you attempted to use functionality that needed\n",
            "an active HTTP request. Consult the documentation on testing for\n",
            "information about how to avoid this problem.\n",
            "ERROR:root:Unexpected exception finding object shape\n",
            "Traceback (most recent call last):\n",
            "  File \"/usr/local/lib/python3.11/dist-packages/google/colab/_debugpy_repr.py\", line 54, in get_shape\n",
            "    shape = getattr(obj, 'shape', None)\n",
            "            ^^^^^^^^^^^^^^^^^^^^^^^^^^^\n",
            "  File \"/usr/local/lib/python3.11/dist-packages/werkzeug/local.py\", line 318, in __get__\n",
            "    obj = instance._get_current_object()\n",
            "          ^^^^^^^^^^^^^^^^^^^^^^^^^^^^^^\n",
            "  File \"/usr/local/lib/python3.11/dist-packages/werkzeug/local.py\", line 519, in _get_current_object\n",
            "    raise RuntimeError(unbound_message) from None\n",
            "RuntimeError: Working outside of request context.\n",
            "\n",
            "This typically means that you attempted to use functionality that needed\n",
            "an active HTTP request. Consult the documentation on testing for\n",
            "information about how to avoid this problem.\n",
            "ERROR:root:Unexpected exception finding object shape\n",
            "Traceback (most recent call last):\n",
            "  File \"/usr/local/lib/python3.11/dist-packages/google/colab/_debugpy_repr.py\", line 54, in get_shape\n",
            "    shape = getattr(obj, 'shape', None)\n",
            "            ^^^^^^^^^^^^^^^^^^^^^^^^^^^\n",
            "  File \"/usr/local/lib/python3.11/dist-packages/werkzeug/local.py\", line 318, in __get__\n",
            "    obj = instance._get_current_object()\n",
            "          ^^^^^^^^^^^^^^^^^^^^^^^^^^^^^^\n",
            "  File \"/usr/local/lib/python3.11/dist-packages/werkzeug/local.py\", line 519, in _get_current_object\n",
            "    raise RuntimeError(unbound_message) from None\n",
            "RuntimeError: Working outside of request context.\n",
            "\n",
            "This typically means that you attempted to use functionality that needed\n",
            "an active HTTP request. Consult the documentation on testing for\n",
            "information about how to avoid this problem.\n",
            "ERROR:root:Unexpected exception finding object shape\n",
            "Traceback (most recent call last):\n",
            "  File \"/usr/local/lib/python3.11/dist-packages/google/colab/_debugpy_repr.py\", line 54, in get_shape\n",
            "    shape = getattr(obj, 'shape', None)\n",
            "            ^^^^^^^^^^^^^^^^^^^^^^^^^^^\n",
            "  File \"/usr/local/lib/python3.11/dist-packages/werkzeug/local.py\", line 318, in __get__\n",
            "    obj = instance._get_current_object()\n",
            "          ^^^^^^^^^^^^^^^^^^^^^^^^^^^^^^\n",
            "  File \"/usr/local/lib/python3.11/dist-packages/werkzeug/local.py\", line 519, in _get_current_object\n",
            "    raise RuntimeError(unbound_message) from None\n",
            "RuntimeError: Working outside of request context.\n",
            "\n",
            "This typically means that you attempted to use functionality that needed\n",
            "an active HTTP request. Consult the documentation on testing for\n",
            "information about how to avoid this problem.\n",
            "ERROR:root:Unexpected exception finding object shape\n",
            "Traceback (most recent call last):\n",
            "  File \"/usr/local/lib/python3.11/dist-packages/google/colab/_debugpy_repr.py\", line 54, in get_shape\n",
            "    shape = getattr(obj, 'shape', None)\n",
            "            ^^^^^^^^^^^^^^^^^^^^^^^^^^^\n",
            "  File \"/usr/local/lib/python3.11/dist-packages/werkzeug/local.py\", line 318, in __get__\n",
            "    obj = instance._get_current_object()\n",
            "          ^^^^^^^^^^^^^^^^^^^^^^^^^^^^^^\n",
            "  File \"/usr/local/lib/python3.11/dist-packages/werkzeug/local.py\", line 519, in _get_current_object\n",
            "    raise RuntimeError(unbound_message) from None\n",
            "RuntimeError: Working outside of request context.\n",
            "\n",
            "This typically means that you attempted to use functionality that needed\n",
            "an active HTTP request. Consult the documentation on testing for\n",
            "information about how to avoid this problem.\n",
            "ERROR:root:Unexpected exception finding object shape\n",
            "Traceback (most recent call last):\n",
            "  File \"/usr/local/lib/python3.11/dist-packages/google/colab/_debugpy_repr.py\", line 54, in get_shape\n",
            "    shape = getattr(obj, 'shape', None)\n",
            "            ^^^^^^^^^^^^^^^^^^^^^^^^^^^\n",
            "  File \"/usr/local/lib/python3.11/dist-packages/werkzeug/local.py\", line 318, in __get__\n",
            "    obj = instance._get_current_object()\n",
            "          ^^^^^^^^^^^^^^^^^^^^^^^^^^^^^^\n",
            "  File \"/usr/local/lib/python3.11/dist-packages/werkzeug/local.py\", line 519, in _get_current_object\n",
            "    raise RuntimeError(unbound_message) from None\n",
            "RuntimeError: Working outside of request context.\n",
            "\n",
            "This typically means that you attempted to use functionality that needed\n",
            "an active HTTP request. Consult the documentation on testing for\n",
            "information about how to avoid this problem.\n",
            "ERROR:root:Unexpected exception finding object shape\n",
            "Traceback (most recent call last):\n",
            "  File \"/usr/local/lib/python3.11/dist-packages/google/colab/_debugpy_repr.py\", line 54, in get_shape\n",
            "    shape = getattr(obj, 'shape', None)\n",
            "            ^^^^^^^^^^^^^^^^^^^^^^^^^^^\n",
            "  File \"/usr/local/lib/python3.11/dist-packages/werkzeug/local.py\", line 318, in __get__\n",
            "    obj = instance._get_current_object()\n",
            "          ^^^^^^^^^^^^^^^^^^^^^^^^^^^^^^\n",
            "  File \"/usr/local/lib/python3.11/dist-packages/werkzeug/local.py\", line 519, in _get_current_object\n",
            "    raise RuntimeError(unbound_message) from None\n",
            "RuntimeError: Working outside of request context.\n",
            "\n",
            "This typically means that you attempted to use functionality that needed\n",
            "an active HTTP request. Consult the documentation on testing for\n",
            "information about how to avoid this problem.\n",
            "ERROR:root:Unexpected exception finding object shape\n",
            "Traceback (most recent call last):\n",
            "  File \"/usr/local/lib/python3.11/dist-packages/google/colab/_debugpy_repr.py\", line 54, in get_shape\n",
            "    shape = getattr(obj, 'shape', None)\n",
            "            ^^^^^^^^^^^^^^^^^^^^^^^^^^^\n",
            "  File \"/usr/local/lib/python3.11/dist-packages/werkzeug/local.py\", line 318, in __get__\n",
            "    obj = instance._get_current_object()\n",
            "          ^^^^^^^^^^^^^^^^^^^^^^^^^^^^^^\n",
            "  File \"/usr/local/lib/python3.11/dist-packages/werkzeug/local.py\", line 519, in _get_current_object\n",
            "    raise RuntimeError(unbound_message) from None\n",
            "RuntimeError: Working outside of request context.\n",
            "\n",
            "This typically means that you attempted to use functionality that needed\n",
            "an active HTTP request. Consult the documentation on testing for\n",
            "information about how to avoid this problem.\n",
            "ERROR:root:Unexpected exception finding object shape\n",
            "Traceback (most recent call last):\n",
            "  File \"/usr/local/lib/python3.11/dist-packages/google/colab/_debugpy_repr.py\", line 54, in get_shape\n",
            "    shape = getattr(obj, 'shape', None)\n",
            "            ^^^^^^^^^^^^^^^^^^^^^^^^^^^\n",
            "  File \"/usr/local/lib/python3.11/dist-packages/werkzeug/local.py\", line 318, in __get__\n",
            "    obj = instance._get_current_object()\n",
            "          ^^^^^^^^^^^^^^^^^^^^^^^^^^^^^^\n",
            "  File \"/usr/local/lib/python3.11/dist-packages/werkzeug/local.py\", line 519, in _get_current_object\n",
            "    raise RuntimeError(unbound_message) from None\n",
            "RuntimeError: Working outside of request context.\n",
            "\n",
            "This typically means that you attempted to use functionality that needed\n",
            "an active HTTP request. Consult the documentation on testing for\n",
            "information about how to avoid this problem.\n",
            "ERROR:root:Unexpected exception finding object shape\n",
            "Traceback (most recent call last):\n",
            "  File \"/usr/local/lib/python3.11/dist-packages/google/colab/_debugpy_repr.py\", line 54, in get_shape\n",
            "    shape = getattr(obj, 'shape', None)\n",
            "            ^^^^^^^^^^^^^^^^^^^^^^^^^^^\n",
            "  File \"/usr/local/lib/python3.11/dist-packages/werkzeug/local.py\", line 318, in __get__\n",
            "    obj = instance._get_current_object()\n",
            "          ^^^^^^^^^^^^^^^^^^^^^^^^^^^^^^\n",
            "  File \"/usr/local/lib/python3.11/dist-packages/werkzeug/local.py\", line 519, in _get_current_object\n",
            "    raise RuntimeError(unbound_message) from None\n",
            "RuntimeError: Working outside of request context.\n",
            "\n",
            "This typically means that you attempted to use functionality that needed\n",
            "an active HTTP request. Consult the documentation on testing for\n",
            "information about how to avoid this problem.\n",
            "ERROR:root:Unexpected exception finding object shape\n",
            "Traceback (most recent call last):\n",
            "  File \"/usr/local/lib/python3.11/dist-packages/google/colab/_debugpy_repr.py\", line 54, in get_shape\n",
            "    shape = getattr(obj, 'shape', None)\n",
            "            ^^^^^^^^^^^^^^^^^^^^^^^^^^^\n",
            "  File \"/usr/local/lib/python3.11/dist-packages/werkzeug/local.py\", line 318, in __get__\n",
            "    obj = instance._get_current_object()\n",
            "          ^^^^^^^^^^^^^^^^^^^^^^^^^^^^^^\n",
            "  File \"/usr/local/lib/python3.11/dist-packages/werkzeug/local.py\", line 519, in _get_current_object\n",
            "    raise RuntimeError(unbound_message) from None\n",
            "RuntimeError: Working outside of request context.\n",
            "\n",
            "This typically means that you attempted to use functionality that needed\n",
            "an active HTTP request. Consult the documentation on testing for\n",
            "information about how to avoid this problem.\n",
            "ERROR:root:Unexpected exception finding object shape\n",
            "Traceback (most recent call last):\n",
            "  File \"/usr/local/lib/python3.11/dist-packages/google/colab/_debugpy_repr.py\", line 54, in get_shape\n",
            "    shape = getattr(obj, 'shape', None)\n",
            "            ^^^^^^^^^^^^^^^^^^^^^^^^^^^\n",
            "  File \"/usr/local/lib/python3.11/dist-packages/werkzeug/local.py\", line 318, in __get__\n",
            "    obj = instance._get_current_object()\n",
            "          ^^^^^^^^^^^^^^^^^^^^^^^^^^^^^^\n",
            "  File \"/usr/local/lib/python3.11/dist-packages/werkzeug/local.py\", line 519, in _get_current_object\n",
            "    raise RuntimeError(unbound_message) from None\n",
            "RuntimeError: Working outside of request context.\n",
            "\n",
            "This typically means that you attempted to use functionality that needed\n",
            "an active HTTP request. Consult the documentation on testing for\n",
            "information about how to avoid this problem.\n",
            "ERROR:root:Unexpected exception finding object shape\n",
            "Traceback (most recent call last):\n",
            "  File \"/usr/local/lib/python3.11/dist-packages/google/colab/_debugpy_repr.py\", line 54, in get_shape\n",
            "    shape = getattr(obj, 'shape', None)\n",
            "            ^^^^^^^^^^^^^^^^^^^^^^^^^^^\n",
            "  File \"/usr/local/lib/python3.11/dist-packages/werkzeug/local.py\", line 318, in __get__\n",
            "    obj = instance._get_current_object()\n",
            "          ^^^^^^^^^^^^^^^^^^^^^^^^^^^^^^\n",
            "  File \"/usr/local/lib/python3.11/dist-packages/werkzeug/local.py\", line 519, in _get_current_object\n",
            "    raise RuntimeError(unbound_message) from None\n",
            "RuntimeError: Working outside of request context.\n",
            "\n",
            "This typically means that you attempted to use functionality that needed\n",
            "an active HTTP request. Consult the documentation on testing for\n",
            "information about how to avoid this problem.\n",
            "ERROR:root:Unexpected exception finding object shape\n",
            "Traceback (most recent call last):\n",
            "  File \"/usr/local/lib/python3.11/dist-packages/google/colab/_debugpy_repr.py\", line 54, in get_shape\n",
            "    shape = getattr(obj, 'shape', None)\n",
            "            ^^^^^^^^^^^^^^^^^^^^^^^^^^^\n",
            "  File \"/usr/local/lib/python3.11/dist-packages/werkzeug/local.py\", line 318, in __get__\n",
            "    obj = instance._get_current_object()\n",
            "          ^^^^^^^^^^^^^^^^^^^^^^^^^^^^^^\n",
            "  File \"/usr/local/lib/python3.11/dist-packages/werkzeug/local.py\", line 519, in _get_current_object\n",
            "    raise RuntimeError(unbound_message) from None\n",
            "RuntimeError: Working outside of request context.\n",
            "\n",
            "This typically means that you attempted to use functionality that needed\n",
            "an active HTTP request. Consult the documentation on testing for\n",
            "information about how to avoid this problem.\n",
            "ERROR:root:Unexpected exception finding object shape\n",
            "Traceback (most recent call last):\n",
            "  File \"/usr/local/lib/python3.11/dist-packages/google/colab/_debugpy_repr.py\", line 54, in get_shape\n",
            "    shape = getattr(obj, 'shape', None)\n",
            "            ^^^^^^^^^^^^^^^^^^^^^^^^^^^\n",
            "  File \"/usr/local/lib/python3.11/dist-packages/werkzeug/local.py\", line 318, in __get__\n",
            "    obj = instance._get_current_object()\n",
            "          ^^^^^^^^^^^^^^^^^^^^^^^^^^^^^^\n",
            "  File \"/usr/local/lib/python3.11/dist-packages/werkzeug/local.py\", line 519, in _get_current_object\n",
            "    raise RuntimeError(unbound_message) from None\n",
            "RuntimeError: Working outside of request context.\n",
            "\n",
            "This typically means that you attempted to use functionality that needed\n",
            "an active HTTP request. Consult the documentation on testing for\n",
            "information about how to avoid this problem.\n",
            "ERROR:root:Unexpected exception finding object shape\n",
            "Traceback (most recent call last):\n",
            "  File \"/usr/local/lib/python3.11/dist-packages/google/colab/_debugpy_repr.py\", line 54, in get_shape\n",
            "    shape = getattr(obj, 'shape', None)\n",
            "            ^^^^^^^^^^^^^^^^^^^^^^^^^^^\n",
            "  File \"/usr/local/lib/python3.11/dist-packages/werkzeug/local.py\", line 318, in __get__\n",
            "    obj = instance._get_current_object()\n",
            "          ^^^^^^^^^^^^^^^^^^^^^^^^^^^^^^\n",
            "  File \"/usr/local/lib/python3.11/dist-packages/werkzeug/local.py\", line 519, in _get_current_object\n",
            "    raise RuntimeError(unbound_message) from None\n",
            "RuntimeError: Working outside of request context.\n",
            "\n",
            "This typically means that you attempted to use functionality that needed\n",
            "an active HTTP request. Consult the documentation on testing for\n",
            "information about how to avoid this problem.\n",
            "ERROR:root:Unexpected exception finding object shape\n",
            "Traceback (most recent call last):\n",
            "  File \"/usr/local/lib/python3.11/dist-packages/google/colab/_debugpy_repr.py\", line 54, in get_shape\n",
            "    shape = getattr(obj, 'shape', None)\n",
            "            ^^^^^^^^^^^^^^^^^^^^^^^^^^^\n",
            "  File \"/usr/local/lib/python3.11/dist-packages/werkzeug/local.py\", line 318, in __get__\n",
            "    obj = instance._get_current_object()\n",
            "          ^^^^^^^^^^^^^^^^^^^^^^^^^^^^^^\n",
            "  File \"/usr/local/lib/python3.11/dist-packages/werkzeug/local.py\", line 519, in _get_current_object\n",
            "    raise RuntimeError(unbound_message) from None\n",
            "RuntimeError: Working outside of request context.\n",
            "\n",
            "This typically means that you attempted to use functionality that needed\n",
            "an active HTTP request. Consult the documentation on testing for\n",
            "information about how to avoid this problem.\n",
            "ERROR:root:Unexpected exception finding object shape\n",
            "Traceback (most recent call last):\n",
            "  File \"/usr/local/lib/python3.11/dist-packages/google/colab/_debugpy_repr.py\", line 54, in get_shape\n",
            "    shape = getattr(obj, 'shape', None)\n",
            "            ^^^^^^^^^^^^^^^^^^^^^^^^^^^\n",
            "  File \"/usr/local/lib/python3.11/dist-packages/werkzeug/local.py\", line 318, in __get__\n",
            "    obj = instance._get_current_object()\n",
            "          ^^^^^^^^^^^^^^^^^^^^^^^^^^^^^^\n",
            "  File \"/usr/local/lib/python3.11/dist-packages/werkzeug/local.py\", line 519, in _get_current_object\n",
            "    raise RuntimeError(unbound_message) from None\n",
            "RuntimeError: Working outside of request context.\n",
            "\n",
            "This typically means that you attempted to use functionality that needed\n",
            "an active HTTP request. Consult the documentation on testing for\n",
            "information about how to avoid this problem.\n",
            "ERROR:root:Unexpected exception finding object shape\n",
            "Traceback (most recent call last):\n",
            "  File \"/usr/local/lib/python3.11/dist-packages/google/colab/_debugpy_repr.py\", line 54, in get_shape\n",
            "    shape = getattr(obj, 'shape', None)\n",
            "            ^^^^^^^^^^^^^^^^^^^^^^^^^^^\n",
            "  File \"/usr/local/lib/python3.11/dist-packages/werkzeug/local.py\", line 318, in __get__\n",
            "    obj = instance._get_current_object()\n",
            "          ^^^^^^^^^^^^^^^^^^^^^^^^^^^^^^\n",
            "  File \"/usr/local/lib/python3.11/dist-packages/werkzeug/local.py\", line 519, in _get_current_object\n",
            "    raise RuntimeError(unbound_message) from None\n",
            "RuntimeError: Working outside of request context.\n",
            "\n",
            "This typically means that you attempted to use functionality that needed\n",
            "an active HTTP request. Consult the documentation on testing for\n",
            "information about how to avoid this problem.\n",
            "ERROR:root:Unexpected exception finding object shape\n",
            "Traceback (most recent call last):\n",
            "  File \"/usr/local/lib/python3.11/dist-packages/google/colab/_debugpy_repr.py\", line 54, in get_shape\n",
            "    shape = getattr(obj, 'shape', None)\n",
            "            ^^^^^^^^^^^^^^^^^^^^^^^^^^^\n",
            "  File \"/usr/local/lib/python3.11/dist-packages/werkzeug/local.py\", line 318, in __get__\n",
            "    obj = instance._get_current_object()\n",
            "          ^^^^^^^^^^^^^^^^^^^^^^^^^^^^^^\n",
            "  File \"/usr/local/lib/python3.11/dist-packages/werkzeug/local.py\", line 519, in _get_current_object\n",
            "    raise RuntimeError(unbound_message) from None\n",
            "RuntimeError: Working outside of request context.\n",
            "\n",
            "This typically means that you attempted to use functionality that needed\n",
            "an active HTTP request. Consult the documentation on testing for\n",
            "information about how to avoid this problem.\n",
            "ERROR:root:Unexpected exception finding object shape\n",
            "Traceback (most recent call last):\n",
            "  File \"/usr/local/lib/python3.11/dist-packages/google/colab/_debugpy_repr.py\", line 54, in get_shape\n",
            "    shape = getattr(obj, 'shape', None)\n",
            "            ^^^^^^^^^^^^^^^^^^^^^^^^^^^\n",
            "  File \"/usr/local/lib/python3.11/dist-packages/werkzeug/local.py\", line 318, in __get__\n",
            "    obj = instance._get_current_object()\n",
            "          ^^^^^^^^^^^^^^^^^^^^^^^^^^^^^^\n",
            "  File \"/usr/local/lib/python3.11/dist-packages/werkzeug/local.py\", line 519, in _get_current_object\n",
            "    raise RuntimeError(unbound_message) from None\n",
            "RuntimeError: Working outside of request context.\n",
            "\n",
            "This typically means that you attempted to use functionality that needed\n",
            "an active HTTP request. Consult the documentation on testing for\n",
            "information about how to avoid this problem.\n",
            "ERROR:root:Unexpected exception finding object shape\n",
            "Traceback (most recent call last):\n",
            "  File \"/usr/local/lib/python3.11/dist-packages/google/colab/_debugpy_repr.py\", line 54, in get_shape\n",
            "    shape = getattr(obj, 'shape', None)\n",
            "            ^^^^^^^^^^^^^^^^^^^^^^^^^^^\n",
            "  File \"/usr/local/lib/python3.11/dist-packages/werkzeug/local.py\", line 318, in __get__\n",
            "    obj = instance._get_current_object()\n",
            "          ^^^^^^^^^^^^^^^^^^^^^^^^^^^^^^\n",
            "  File \"/usr/local/lib/python3.11/dist-packages/werkzeug/local.py\", line 519, in _get_current_object\n",
            "    raise RuntimeError(unbound_message) from None\n",
            "RuntimeError: Working outside of request context.\n",
            "\n",
            "This typically means that you attempted to use functionality that needed\n",
            "an active HTTP request. Consult the documentation on testing for\n",
            "information about how to avoid this problem.\n",
            "ERROR:root:Unexpected exception finding object shape\n",
            "Traceback (most recent call last):\n",
            "  File \"/usr/local/lib/python3.11/dist-packages/google/colab/_debugpy_repr.py\", line 54, in get_shape\n",
            "    shape = getattr(obj, 'shape', None)\n",
            "            ^^^^^^^^^^^^^^^^^^^^^^^^^^^\n",
            "  File \"/usr/local/lib/python3.11/dist-packages/werkzeug/local.py\", line 318, in __get__\n",
            "    obj = instance._get_current_object()\n",
            "          ^^^^^^^^^^^^^^^^^^^^^^^^^^^^^^\n",
            "  File \"/usr/local/lib/python3.11/dist-packages/werkzeug/local.py\", line 519, in _get_current_object\n",
            "    raise RuntimeError(unbound_message) from None\n",
            "RuntimeError: Working outside of request context.\n",
            "\n",
            "This typically means that you attempted to use functionality that needed\n",
            "an active HTTP request. Consult the documentation on testing for\n",
            "information about how to avoid this problem.\n",
            "ERROR:root:Unexpected exception finding object shape\n",
            "Traceback (most recent call last):\n",
            "  File \"/usr/local/lib/python3.11/dist-packages/google/colab/_debugpy_repr.py\", line 54, in get_shape\n",
            "    shape = getattr(obj, 'shape', None)\n",
            "            ^^^^^^^^^^^^^^^^^^^^^^^^^^^\n",
            "  File \"/usr/local/lib/python3.11/dist-packages/werkzeug/local.py\", line 318, in __get__\n",
            "    obj = instance._get_current_object()\n",
            "          ^^^^^^^^^^^^^^^^^^^^^^^^^^^^^^\n",
            "  File \"/usr/local/lib/python3.11/dist-packages/werkzeug/local.py\", line 519, in _get_current_object\n",
            "    raise RuntimeError(unbound_message) from None\n",
            "RuntimeError: Working outside of request context.\n",
            "\n",
            "This typically means that you attempted to use functionality that needed\n",
            "an active HTTP request. Consult the documentation on testing for\n",
            "information about how to avoid this problem.\n",
            "ERROR:root:Unexpected exception finding object shape\n",
            "Traceback (most recent call last):\n",
            "  File \"/usr/local/lib/python3.11/dist-packages/google/colab/_debugpy_repr.py\", line 54, in get_shape\n",
            "    shape = getattr(obj, 'shape', None)\n",
            "            ^^^^^^^^^^^^^^^^^^^^^^^^^^^\n",
            "  File \"/usr/local/lib/python3.11/dist-packages/werkzeug/local.py\", line 318, in __get__\n",
            "    obj = instance._get_current_object()\n",
            "          ^^^^^^^^^^^^^^^^^^^^^^^^^^^^^^\n",
            "  File \"/usr/local/lib/python3.11/dist-packages/werkzeug/local.py\", line 519, in _get_current_object\n",
            "    raise RuntimeError(unbound_message) from None\n",
            "RuntimeError: Working outside of request context.\n",
            "\n",
            "This typically means that you attempted to use functionality that needed\n",
            "an active HTTP request. Consult the documentation on testing for\n",
            "information about how to avoid this problem.\n",
            "ERROR:root:Unexpected exception finding object shape\n",
            "Traceback (most recent call last):\n",
            "  File \"/usr/local/lib/python3.11/dist-packages/google/colab/_debugpy_repr.py\", line 54, in get_shape\n",
            "    shape = getattr(obj, 'shape', None)\n",
            "            ^^^^^^^^^^^^^^^^^^^^^^^^^^^\n",
            "  File \"/usr/local/lib/python3.11/dist-packages/werkzeug/local.py\", line 318, in __get__\n",
            "    obj = instance._get_current_object()\n",
            "          ^^^^^^^^^^^^^^^^^^^^^^^^^^^^^^\n",
            "  File \"/usr/local/lib/python3.11/dist-packages/werkzeug/local.py\", line 519, in _get_current_object\n",
            "    raise RuntimeError(unbound_message) from None\n",
            "RuntimeError: Working outside of request context.\n",
            "\n",
            "This typically means that you attempted to use functionality that needed\n",
            "an active HTTP request. Consult the documentation on testing for\n",
            "information about how to avoid this problem.\n",
            "ERROR:root:Unexpected exception finding object shape\n",
            "Traceback (most recent call last):\n",
            "  File \"/usr/local/lib/python3.11/dist-packages/google/colab/_debugpy_repr.py\", line 54, in get_shape\n",
            "    shape = getattr(obj, 'shape', None)\n",
            "            ^^^^^^^^^^^^^^^^^^^^^^^^^^^\n",
            "  File \"/usr/local/lib/python3.11/dist-packages/werkzeug/local.py\", line 318, in __get__\n",
            "    obj = instance._get_current_object()\n",
            "          ^^^^^^^^^^^^^^^^^^^^^^^^^^^^^^\n",
            "  File \"/usr/local/lib/python3.11/dist-packages/werkzeug/local.py\", line 519, in _get_current_object\n",
            "    raise RuntimeError(unbound_message) from None\n",
            "RuntimeError: Working outside of request context.\n",
            "\n",
            "This typically means that you attempted to use functionality that needed\n",
            "an active HTTP request. Consult the documentation on testing for\n",
            "information about how to avoid this problem.\n",
            "ERROR:root:Unexpected exception finding object shape\n",
            "Traceback (most recent call last):\n",
            "  File \"/usr/local/lib/python3.11/dist-packages/google/colab/_debugpy_repr.py\", line 54, in get_shape\n",
            "    shape = getattr(obj, 'shape', None)\n",
            "            ^^^^^^^^^^^^^^^^^^^^^^^^^^^\n",
            "  File \"/usr/local/lib/python3.11/dist-packages/werkzeug/local.py\", line 318, in __get__\n",
            "    obj = instance._get_current_object()\n",
            "          ^^^^^^^^^^^^^^^^^^^^^^^^^^^^^^\n",
            "  File \"/usr/local/lib/python3.11/dist-packages/werkzeug/local.py\", line 519, in _get_current_object\n",
            "    raise RuntimeError(unbound_message) from None\n",
            "RuntimeError: Working outside of request context.\n",
            "\n",
            "This typically means that you attempted to use functionality that needed\n",
            "an active HTTP request. Consult the documentation on testing for\n",
            "information about how to avoid this problem.\n",
            "WARNING:pyngrok.process.ngrok:t=2025-06-21T02:45:51+0000 lvl=warn msg=\"Stopping forwarder\" name=http-5000-9209b487-bdf2-4b66-bf85-eac1cfac3138 acceptErr=\"failed to accept connection: Listener closed\"\n",
            "WARNING:pyngrok.process.ngrok:t=2025-06-21T02:45:51+0000 lvl=warn msg=\"Error restarting forwarder\" name=http-5000-9209b487-bdf2-4b66-bf85-eac1cfac3138 err=\"failed to start tunnel: session closed\"\n"
          ]
        }
      ]
    }
  ]
}